<?xml version='1.0'?>

<robot name="beetle" xmlns:xacro="http://www.ros.org/wiki/xacro">
  
  <xacro:include filename="inertial_macros.xacro"/>
  <xacro:include filename="beetle_robot.gazebo.xacro"/>
  
    <material name="white">
        <color rgba="1 1 1 1" />
    </material>

    <material name="orange">
        <color rgba="1 0.3 0.1 1"/>
    </material>

    <material name="blue">
        <color rgba="0.2 0.2 1 1"/>
    </material>

    <material name="black">
        <color rgba="0 0 0 1"/>
    </material>

    <material name="red">
        <color rgba="1 0 0 1"/>
    </material>

    <link name="base_footprint"/>

    <joint name="base_joint" type="fixed">
        <parent link="base_footprint"/>
        <child link="base_link"/>
        <origin xyz="0 0 0.001"/>
    </joint>

    <link name="base_link">
        <visual>
          <origin xyz="0 0 0.001"/>
          <geometry>
              <box size="0.1 0.1 0.01"/>
          </geometry>
          <material name="black"/>
        </visual>
        <collision>
          <origin xyz="0 0 0.001"/>
          <geometry>
              <box size="0.1 0.1 0.01"/>
          </geometry>
        </collision>
        <xacro:inertial_box mass="10" x="0.0" y="0.0" z="0.001">
            <origin xyz="0 0 0.001" rpy="0 0 0"/>
        </xacro:inertial_box>
    </link>
    
    <gazebo reference="base_link">
        <material>Gazebo/Black</material>
    </gazebo>
    
    <joint name="revolute_joint" type="continuous">
        <parent link="base_link"/>
        <child link="main_body"/>
        <origin xyz="0 0 0.005" rpy="0 0 0" />
        <axis xyz="0 0 1"/>
    </joint>

    <link name="main_body">
        <visual>
          <origin xyz="0 0 0.04"/>
          <geometry>
              <cylinder length="0.08" radius="0.01"/>
          </geometry>
          <material name="white"/>
        </visual>
        <collision>
          <origin xyz="0 0 0.04"/>
          <geometry>
              <cylinder length="0.08" radius="0.01"/>
          </geometry>
        </collision>
        <xacro:inertial_cylinder mass="10" length="0.08" radius="0.01">
            <origin xyz="0 0 0.04" rpy="0 0 0"/>
        </xacro:inertial_cylinder>
    </link>

    <gazebo reference="main_body">
        <material>Gazebo/White</material>
    </gazebo>

    <joint name="shoulder_joint" type="revolute">
        <parent link="main_body"/>
        <child link="upper_arm"/>
        <origin xyz="0 0 0.09" rpy="0 0 0" />
        <axis xyz="1 0 0"/>
        <limit effort="1000.0" lower="-${pi}" upper="0" velocity="0.5"/>
    </joint>

    <link name="upper_arm">
        <visual>
          <origin xyz="0 0 0.04"/>
          <geometry>
              <cylinder length="0.08" radius="0.01"/>
          </geometry>
          <material name="white"/>
        </visual>
        <collision>
          <origin xyz="0 0 0.08"/>
          <geometry>
              <cylinder length="0.08" radius="0.01"/>
          </geometry>
        </collision>
        <xacro:inertial_cylinder mass="10" length="0.08" radius="0.01">
            <origin xyz="0 0 0.08" rpy="0 0 0"/>
        </xacro:inertial_cylinder>
    </link>

    <gazebo reference="upper_arm">
        <material>Gazebo/White</material>
    </gazebo>
    
    <joint name="elbow_joint" type="revolute">
        <parent link="upper_arm"/>
        <child link="forearm"/>
        <origin xyz="0 0 0.09" rpy="0 0 0" />
        <axis xyz="1 0 0"/>
        <limit effort="1000.0" lower="-${pi}" upper="0" velocity="0.5"/>
    </joint>
    
    <link name="forearm">
        <visual>
          <origin xyz="0 0 0.04"/>
          <geometry>
              <cylinder length="0.08" radius="0.01"/>
          </geometry>
          <material name="white"/>
        </visual>
        <collision>
          <origin xyz="0 0 0.08"/>
          <geometry>
              <cylinder length="0.08" radius="0.01"/>
          </geometry>
        </collision>
        <xacro:inertial_cylinder mass="10" length="0.08" radius="0.01">
            <origin xyz="0 0 0.08" rpy="0 0 0"/>
        </xacro:inertial_cylinder>
    </link>

    <gazebo reference="forearm">
        <material>Gazebo/White</material>
    </gazebo>
    
    <joint name="wrist_joint" type="revolute">
        <parent link="forearm"/>
        <child link="hand"/>
        <origin xyz="0 0 0.08" rpy="0 0 0" />
        <axis xyz="1 0 0"/>
        <limit effort="1000.0" lower="-${pi}" upper="0" velocity="0.5"/>
    </joint>
    
    <link name="hand">
        <visual>
          <origin xyz="0 -0.005 0.02"/>
          <geometry>
              <box size="0.03 0.005 0.04"/>
          </geometry>
          <material name="blue"/>
        </visual>
        <collision>
          <origin xyz="0 -0.005 0.03"/>
          <geometry>
              <box size="0.03 0.005 0.04"/>
          </geometry>
        </collision>
        <xacro:inertial_box mass="10" x="0.0" y="-0.005" z="0.02">
            <origin xyz="0 -0.005 0.02" rpy="0 0 0"/>
        </xacro:inertial_box>
    </link>
        
    <gazebo reference="hand">
        <material>Gazebo/Blue</material>
    </gazebo>        
       
  <joint name="imu_joint" type="fixed">
    <parent link="base_link"/>
    <child link="imu_link"/>
    <origin xyz="-0.032 0 0.068" rpy="0 0 0"/>
  </joint>

  <link name="imu_link"/>
    
</robot>
